from fastapi import FastAPI, UploadFile, Form
from fastapi.staticfiles import StaticFiles
from pymongo import MongoClient
from datetime import datetime
import shutil

app = FastAPI()

# Connect MongoDB
client = MongoClient("mongodb://localhost:27017/")
db = client["egg_database"]
collection = db["eggs"]

# Mount images directory so Flutter can access
app.mount("/images", StaticFiles(directory="images"), name="images")

@app.post("/egg")
async def upload_egg(image: UploadFile, size: str = Form(...), grade: str = Form(...)):
    # Save image file
    filepath = f"images/{image.filename}"
    with open(filepath, "wb") as buffer:
        shutil.copyfileobj(image.file, buffer)
    
    # Save record to DB
    record = {
        "image": image.filename,
        "size": size,
        "grade": grade,
        "timestamp": datetime.now().isoformat()
    }
    collection.insert_one(record)
    return {"message": "Egg data saved!"}

@app.get("/eggs")
def get_eggs():
    # Return eggs sorted by newest first
    eggs = list(collection.find({}, {"_id": 0}).sort("timestamp", -1))
    return {"eggs": eggs}
// eggs = list(collection.find({}, {"_id": 0}))
sudo systemctl status mongod
(.venv) group4PI@group4PI:~/Documents/test $ uvicorn main:app --host 0.0.0.0 --port 8000
INFO:     Started server process [17962]
INFO:     Waiting for application startup.
INFO:     Application startup complete.
INFO:     Uvicorn running on http://0.0.0.0:8000 (Press CTRL+C to quit)
INFO:     10.232.51.78:56498 - "GET /eggs HTTP/1.1" 500 Internal Server Error
ERROR:    Exception in ASGI application
Traceback (most recent call last):
  File "/home/group4PI/Documents/test/.venv/lib/python3.11/site-packages/uvicorn/protocols/http/h11_impl.py", line 403, in run_asgi
    result = await app(  # type: ignore[func-returns-value]
             ^^^^^^^^^^^^^^^^^^^^^^^^^^^^^^^^^^^^^^^^^^^^^^
  File "/home/group4PI/Documents/test/.venv/lib/python3.11/site-packages/uvicorn/middleware/proxy_headers.py", line 60, in __call__
    return await self.app(scope, receive, send)
           ^^^^^^^^^^^^^^^^^^^^^^^^^^^^^^^^^^^^
  File "/home/group4PI/Documents/test/.venv/lib/python3.11/site-packages/fastapi/applications.py", line 1133, in __call__
    await super().__call__(scope, receive, send)
  File "/home/group4PI/Documents/test/.venv/lib/python3.11/site-packages/starlette/applications.py", line 113, in __call__
    await self.middleware_stack(scope, receive, send)
  File "/home/group4PI/Documents/test/.venv/lib/python3.11/site-packages/starlette/middleware/errors.py", line 186, in __call__
    raise exc
  File "/home/group4PI/Documents/test/.venv/lib/python3.11/site-packages/starlette/middleware/errors.py", line 164, in __call__
    await self.app(scope, receive, _send)
  File "/home/group4PI/Documents/test/.venv/lib/python3.11/site-packages/starlette/middleware/exceptions.py", line 63, in __call__
    await wrap_app_handling_exceptions(self.app, conn)(scope, receive, send)
  File "/home/group4PI/Documents/test/.venv/lib/python3.11/site-packages/starlette/_exception_handler.py", line 53, in wrapped_app
    raise exc
  File "/home/group4PI/Documents/test/.venv/lib/python3.11/site-packages/starlette/_exception_handler.py", line 42, in wrapped_app
    await app(scope, receive, sender)
  File "/home/group4PI/Documents/test/.venv/lib/python3.11/site-packages/fastapi/middleware/asyncexitstack.py", line 18, in __call__
    await self.app(scope, receive, send)
  File "/home/group4PI/Documents/test/.venv/lib/python3.11/site-packages/starlette/routing.py", line 716, in __call__
    await self.middleware_stack(scope, receive, send)
  File "/home/group4PI/Documents/test/.venv/lib/python3.11/site-packages/starlette/routing.py", line 736, in app
    await route.handle(scope, receive, send)
  File "/home/group4PI/Documents/test/.venv/lib/python3.11/site-packages/starlette/routing.py", line 290, in handle
    await self.app(scope, receive, send)
  File "/home/group4PI/Documents/test/.venv/lib/python3.11/site-packages/fastapi/routing.py", line 123, in app
    await wrap_app_handling_exceptions(app, request)(scope, receive, send)
  File "/home/group4PI/Documents/test/.venv/lib/python3.11/site-packages/starlette/_exception_handler.py", line 53, in wrapped_app
    raise exc
  File "/home/group4PI/Documents/test/.venv/lib/python3.11/site-packages/starlette/_exception_handler.py", line 42, in wrapped_app
    await app(scope, receive, sender)
  File "/home/group4PI/Documents/test/.venv/lib/python3.11/site-packages/fastapi/routing.py", line 109, in app
    response = await f(request)
               ^^^^^^^^^^^^^^^^
  File "/home/group4PI/Documents/test/.venv/lib/python3.11/site-packages/fastapi/routing.py", line 387, in app
    raw_response = await run_endpoint_function(
                   ^^^^^^^^^^^^^^^^^^^^^^^^^^^^
  File "/home/group4PI/Documents/test/.venv/lib/python3.11/site-packages/fastapi/routing.py", line 290, in run_endpoint_function
    return await run_in_threadpool(dependant.call, **values)
           ^^^^^^^^^^^^^^^^^^^^^^^^^^^^^^^^^^^^^^^^^^^^^^^^^
  File "/home/group4PI/Documents/test/.venv/lib/python3.11/site-packages/starlette/concurrency.py", line 38, in run_in_threadpool
    return await anyio.to_thread.run_sync(func)
           ^^^^^^^^^^^^^^^^^^^^^^^^^^^^^^^^^^^^
  File "/home/group4PI/Documents/test/.venv/lib/python3.11/site-packages/anyio/to_thread.py", line 56, in run_sync
    return await get_async_backend().run_sync_in_worker_thread(
           ^^^^^^^^^^^^^^^^^^^^^^^^^^^^^^^^^^^^^^^^^^^^^^^^^^^^
  File "/home/group4PI/Documents/test/.venv/lib/python3.11/site-packages/anyio/_backends/_asyncio.py", line 2485, in run_sync_in_worker_thread
    return await future
           ^^^^^^^^^^^^
  File "/home/group4PI/Documents/test/.venv/lib/python3.11/site-packages/anyio/_backends/_asyncio.py", line 976, in run
    result = context.run(func, *args)
             ^^^^^^^^^^^^^^^^^^^^^^^^
  File "/home/group4PI/Documents/test/main.py", line 37, in get_eggs
    eggs = list(collection.find({}, {"_id": 0}))
           ^^^^^^^^^^^^^^^^^^^^^^^^^^^^^^^^^^^^^
  File "/home/group4PI/Documents/test/.venv/lib/python3.11/site-packages/pymongo/synchronous/cursor.py", line 1289, in __next__
    return self.next()
           ^^^^^^^^^^^
  File "/home/group4PI/Documents/test/.venv/lib/python3.11/site-packages/pymongo/synchronous/cursor.py", line 1265, in next
    if len(self._data) or self._refresh():
                          ^^^^^^^^^^^^^^^
  File "/home/group4PI/Documents/test/.venv/lib/python3.11/site-packages/pymongo/synchronous/cursor.py", line 1213, in _refresh
    self._send_message(q)
  File "/home/group4PI/Documents/test/.venv/lib/python3.11/site-packages/pymongo/synchronous/cursor.py", line 1108, in _send_message
    response = client._run_operation(
               ^^^^^^^^^^^^^^^^^^^^^^
  File "/home/group4PI/Documents/test/.venv/lib/python3.11/site-packages/pymongo/_csot.py", line 125, in csot_wrapper
    return func(self, *args, **kwargs)
           ^^^^^^^^^^^^^^^^^^^^^^^^^^^
  File "/home/group4PI/Documents/test/.venv/lib/python3.11/site-packages/pymongo/synchronous/mongo_client.py", line 1938, in _run_operation
    return self._retryable_read(
           ^^^^^^^^^^^^^^^^^^^^^
  File "/home/group4PI/Documents/test/.venv/lib/python3.11/site-packages/pymongo/synchronous/mongo_client.py", line 2047, in _retryable_read
    return self._retry_internal(
           ^^^^^^^^^^^^^^^^^^^^^
  File "/home/group4PI/Documents/test/.venv/lib/python3.11/site-packages/pymongo/_csot.py", line 125, in csot_wrapper
    return func(self, *args, **kwargs)
           ^^^^^^^^^^^^^^^^^^^^^^^^^^^
  File "/home/group4PI/Documents/test/.venv/lib/python3.11/site-packages/pymongo/synchronous/mongo_client.py", line 2014, in _retry_internal
    ).run()
      ^^^^^
  File "/home/group4PI/Documents/test/.venv/lib/python3.11/site-packages/pymongo/synchronous/mongo_client.py", line 2765, in run
    return self._read() if self._is_read else self._write()
           ^^^^^^^^^^^^
  File "/home/group4PI/Documents/test/.venv/lib/python3.11/site-packages/pymongo/synchronous/mongo_client.py", line 2910, in _read
    self._server = self._get_server()
                   ^^^^^^^^^^^^^^^^^^
  File "/home/group4PI/Documents/test/.venv/lib/python3.11/site-packages/pymongo/synchronous/mongo_client.py", line 2858, in _get_server
    return self._client._select_server(
           ^^^^^^^^^^^^^^^^^^^^^^^^^^^^
  File "/home/group4PI/Documents/test/.venv/lib/python3.11/site-packages/pymongo/synchronous/mongo_client.py", line 1833, in _select_server
    server = topology.select_server(
             ^^^^^^^^^^^^^^^^^^^^^^^
  File "/home/group4PI/Documents/test/.venv/lib/python3.11/site-packages/pymongo/synchronous/topology.py", line 409, in select_server
    server = self._select_server(
             ^^^^^^^^^^^^^^^^^^^^
  File "/home/group4PI/Documents/test/.venv/lib/python3.11/site-packages/pymongo/synchronous/topology.py", line 387, in _select_server
    servers = self.select_servers(
              ^^^^^^^^^^^^^^^^^^^^
  File "/home/group4PI/Documents/test/.venv/lib/python3.11/site-packages/pymongo/synchronous/topology.py", line 294, in select_servers
    server_descriptions = self._select_servers_loop(
                          ^^^^^^^^^^^^^^^^^^^^^^^^^^
  File "/home/group4PI/Documents/test/.venv/lib/python3.11/site-packages/pymongo/synchronous/topology.py", line 344, in _select_servers_loop
    raise ServerSelectionTimeoutError(
pymongo.errors.ServerSelectionTimeoutError: localhost:27017: [Errno 111] Connection refused (configured timeouts: socketTimeoutMS: 20000.0ms, connectTimeoutMS: 20000.0ms), Timeout: 30s, Topology Description: <TopologyDescription id: 68e3b13d8f7d560c5b56863e, topology_type: Unknown, servers: [<ServerDescription ('localhost', 27017) server_type: Unknown, rtt: None, error=AutoReconnect('localhost:27017: [Errno 111] Connection refused (configured timeouts: socketTimeoutMS: 20000.0ms, connectTimeoutMS: 20000.0ms)')>]>
INFO:     10.227.160.8:65262 - "GET /eggs HTTP/1.1" 500 Internal Server Error
ERROR:    Exception in ASGI application
Traceback (most recent call last):
  File "/home/group4PI/Documents/test/.venv/lib/python3.11/site-packages/uvicorn/protocols/http/h11_impl.py", line 403, in run_asgi
    result = await app(  # type: ignore[func-returns-value]
             ^^^^^^^^^^^^^^^^^^^^^^^^^^^^^^^^^^^^^^^^^^^^^^
  File "/home/group4PI/Documents/test/.venv/lib/python3.11/site-packages/uvicorn/middleware/proxy_headers.py", line 60, in __call__
    return await self.app(scope, receive, send)
           ^^^^^^^^^^^^^^^^^^^^^^^^^^^^^^^^^^^^
  File "/home/group4PI/Documents/test/.venv/lib/python3.11/site-packages/fastapi/applications.py", line 1133, in __call__
    await super().__call__(scope, receive, send)
  File "/home/group4PI/Documents/test/.venv/lib/python3.11/site-packages/starlette/applications.py", line 113, in __call__
    await self.middleware_stack(scope, receive, send)
  File "/home/group4PI/Documents/test/.venv/lib/python3.11/site-packages/starlette/middleware/errors.py", line 186, in __call__
    raise exc
  File "/home/group4PI/Documents/test/.venv/lib/python3.11/site-packages/starlette/middleware/errors.py", line 164, in __call__
    await self.app(scope, receive, _send)
  File "/home/group4PI/Documents/test/.venv/lib/python3.11/site-packages/starlette/middleware/exceptions.py", line 63, in __call__
    await wrap_app_handling_exceptions(self.app, conn)(scope, receive, send)
  File "/home/group4PI/Documents/test/.venv/lib/python3.11/site-packages/starlette/_exception_handler.py", line 53, in wrapped_app
    raise exc
  File "/home/group4PI/Documents/test/.venv/lib/python3.11/site-packages/starlette/_exception_handler.py", line 42, in wrapped_app
    await app(scope, receive, sender)
  File "/home/group4PI/Documents/test/.venv/lib/python3.11/site-packages/fastapi/middleware/asyncexitstack.py", line 18, in __call__
    await self.app(scope, receive, send)
  File "/home/group4PI/Documents/test/.venv/lib/python3.11/site-packages/starlette/routing.py", line 716, in __call__
    await self.middleware_stack(scope, receive, send)
  File "/home/group4PI/Documents/test/.venv/lib/python3.11/site-packages/starlette/routing.py", line 736, in app
    await route.handle(scope, receive, send)
  File "/home/group4PI/Documents/test/.venv/lib/python3.11/site-packages/starlette/routing.py", line 290, in handle
    await self.app(scope, receive, send)
  File "/home/group4PI/Documents/test/.venv/lib/python3.11/site-packages/fastapi/routing.py", line 123, in app
    await wrap_app_handling_exceptions(app, request)(scope, receive, send)
  File "/home/group4PI/Documents/test/.venv/lib/python3.11/site-packages/starlette/_exception_handler.py", line 53, in wrapped_app
    raise exc
  File "/home/group4PI/Documents/test/.venv/lib/python3.11/site-packages/starlette/_exception_handler.py", line 42, in wrapped_app
    await app(scope, receive, sender)
  File "/home/group4PI/Documents/test/.venv/lib/python3.11/site-packages/fastapi/routing.py", line 109, in app
    response = await f(request)
               ^^^^^^^^^^^^^^^^
  File "/home/group4PI/Documents/test/.venv/lib/python3.11/site-packages/fastapi/routing.py", line 387, in app
    raw_response = await run_endpoint_function(
                   ^^^^^^^^^^^^^^^^^^^^^^^^^^^^
  File "/home/group4PI/Documents/test/.venv/lib/python3.11/site-packages/fastapi/routing.py", line 290, in run_endpoint_function
    return await run_in_threadpool(dependant.call, **values)
           ^^^^^^^^^^^^^^^^^^^^^^^^^^^^^^^^^^^^^^^^^^^^^^^^^
  File "/home/group4PI/Documents/test/.venv/lib/python3.11/site-packages/starlette/concurrency.py", line 38, in run_in_threadpool
    return await anyio.to_thread.run_sync(func)
           ^^^^^^^^^^^^^^^^^^^^^^^^^^^^^^^^^^^^
  File "/home/group4PI/Documents/test/.venv/lib/python3.11/site-packages/anyio/to_thread.py", line 56, in run_sync
    return await get_async_backend().run_sync_in_worker_thread(
           ^^^^^^^^^^^^^^^^^^^^^^^^^^^^^^^^^^^^^^^^^^^^^^^^^^^^
  File "/home/group4PI/Documents/test/.venv/lib/python3.11/site-packages/anyio/_backends/_asyncio.py", line 2485, in run_sync_in_worker_thread
    return await future
           ^^^^^^^^^^^^
  File "/home/group4PI/Documents/test/.venv/lib/python3.11/site-packages/anyio/_backends/_asyncio.py", line 976, in run
    result = context.run(func, *args)
             ^^^^^^^^^^^^^^^^^^^^^^^^
  File "/home/group4PI/Documents/test/main.py", line 37, in get_eggs
    eggs = list(collection.find({}, {"_id": 0}))
           ^^^^^^^^^^^^^^^^^^^^^^^^^^^^^^^^^^^^^
  File "/home/group4PI/Documents/test/.venv/lib/python3.11/site-packages/pymongo/synchronous/cursor.py", line 1289, in __next__
    return self.next()
           ^^^^^^^^^^^
  File "/home/group4PI/Documents/test/.venv/lib/python3.11/site-packages/pymongo/synchronous/cursor.py", line 1265, in next
    if len(self._data) or self._refresh():
                          ^^^^^^^^^^^^^^^
  File "/home/group4PI/Documents/test/.venv/lib/python3.11/site-packages/pymongo/synchronous/cursor.py", line 1213, in _refresh
    self._send_message(q)
  File "/home/group4PI/Documents/test/.venv/lib/python3.11/site-packages/pymongo/synchronous/cursor.py", line 1108, in _send_message
    response = client._run_operation(
               ^^^^^^^^^^^^^^^^^^^^^^
  File "/home/group4PI/Documents/test/.venv/lib/python3.11/site-packages/pymongo/_csot.py", line 125, in csot_wrapper
    return func(self, *args, **kwargs)
           ^^^^^^^^^^^^^^^^^^^^^^^^^^^
  File "/home/group4PI/Documents/test/.venv/lib/python3.11/site-packages/pymongo/synchronous/mongo_client.py", line 1938, in _run_operation
    return self._retryable_read(
           ^^^^^^^^^^^^^^^^^^^^^
  File "/home/group4PI/Documents/test/.venv/lib/python3.11/site-packages/pymongo/synchronous/mongo_client.py", line 2047, in _retryable_read
    return self._retry_internal(
           ^^^^^^^^^^^^^^^^^^^^^
  File "/home/group4PI/Documents/test/.venv/lib/python3.11/site-packages/pymongo/_csot.py", line 125, in csot_wrapper
    return func(self, *args, **kwargs)
           ^^^^^^^^^^^^^^^^^^^^^^^^^^^
  File "/home/group4PI/Documents/test/.venv/lib/python3.11/site-packages/pymongo/synchronous/mongo_client.py", line 2014, in _retry_internal
    ).run()
      ^^^^^
  File "/home/group4PI/Documents/test/.venv/lib/python3.11/site-packages/pymongo/synchronous/mongo_client.py", line 2765, in run
    return self._read() if self._is_read else self._write()
           ^^^^^^^^^^^^
  File "/home/group4PI/Documents/test/.venv/lib/python3.11/site-packages/pymongo/synchronous/mongo_client.py", line 2910, in _read
    self._server = self._get_server()
                   ^^^^^^^^^^^^^^^^^^
  File "/home/group4PI/Documents/test/.venv/lib/python3.11/site-packages/pymongo/synchronous/mongo_client.py", line 2858, in _get_server
    return self._client._select_server(
           ^^^^^^^^^^^^^^^^^^^^^^^^^^^^
  File "/home/group4PI/Documents/test/.venv/lib/python3.11/site-packages/pymongo/synchronous/mongo_client.py", line 1833, in _select_server
    server = topology.select_server(
             ^^^^^^^^^^^^^^^^^^^^^^^
  File "/home/group4PI/Documents/test/.venv/lib/python3.11/site-packages/pymongo/synchronous/topology.py", line 409, in select_server
    server = self._select_server(
             ^^^^^^^^^^^^^^^^^^^^
  File "/home/group4PI/Documents/test/.venv/lib/python3.11/site-packages/pymongo/synchronous/topology.py", line 387, in _select_server
    servers = self.select_servers(
              ^^^^^^^^^^^^^^^^^^^^
  File "/home/group4PI/Documents/test/.venv/lib/python3.11/site-packages/pymongo/synchronous/topology.py", line 294, in select_servers
    server_descriptions = self._select_servers_loop(
                          ^^^^^^^^^^^^^^^^^^^^^^^^^^
  File "/home/group4PI/Documents/test/.venv/lib/python3.11/site-packages/pymongo/synchronous/topology.py", line 344, in _select_servers_loop
    raise ServerSelectionTimeoutError(
pymongo.errors.ServerSelectionTimeoutError: localhost:27017: [Errno 111] Connection refused (configured timeouts: socketTimeoutMS: 20000.0ms, connectTimeoutMS: 20000.0ms), Timeout: 30s, Topology Description: <TopologyDescription id: 68e3b13d8f7d560c5b56863e, topology_type: Unknown, servers: [<ServerDescription ('localhost', 27017) server_type: Unknown, rtt: None, error=AutoReconnect('localhost:27017: [Errno 111] Connection refused (configured timeouts: socketTimeoutMS: 20000.0ms, connectTimeoutMS: 20000.0ms)')>]>
^CINFO:     Shutting down
INFO:     Waiting for application shutdown.
INFO:     Application shutdown complete.
INFO:     Finished server process [17962]
(.venv) group4PI@group4PI:~/Documents/test $ sudo systemctl status mongod
Unit mongod.service could not be found.
(.venv) group4PI@group4PI:~/Documents/test $ 
